<?xml version="1.0" ?>
<!-- =================================================================================== -->
<!-- |    This document was autogenerated by xacro from Pendel.xacro                   | -->
<!-- |    EDITING THIS FILE BY HAND IS NOT RECOMMENDED                                 | -->
<!-- =================================================================================== -->
<robot name="Pendel">
  <material name="silver">
    <color rgba="0.700 0.700 0.700 1.000"/>
  </material>
  <transmission name="pendelGelenk_tran">
    <type>transmission_interface/SimpleTransmission</type>
    <joint name="pendelGelenk">
      <hardwareInterface>hardware_interface/EffortJointInterface</hardwareInterface>
    </joint>
    <actuator name="pendelGelenk_actr">
      <hardwareInterface>hardware_interface/EffortJointInterface</hardwareInterface>
      <mechanicalReduction>1</mechanicalReduction>
    </actuator>
  </transmission>
  <transmission name="rotaryGelenk_tran">
    <type>transmission_interface/SimpleTransmission</type>
    <joint name="rotaryGelenk">
      <hardwareInterface>hardware_interface/EffortJointInterface</hardwareInterface>
    </joint>
    <actuator name="rotaryGelenk_actr">
      <hardwareInterface>hardware_interface/EffortJointInterface</hardwareInterface>
      <mechanicalReduction>1</mechanicalReduction>
    </actuator>
  </transmission>
  <gazebo>
    <plugin filename="libgazebo_ros_control.so" name="control"/>
  </gazebo>
  <gazebo reference="base_link">
    <material>Gazebo/Silver</material>
    <mu1>0.2</mu1>
    <mu2>0.2</mu2>
    <selfCollide>true</selfCollide>
    <gravity>true</gravity>
  </gazebo>
  <gazebo reference="Pendel_1">
    <material>Gazebo/Silver</material>
    <mu1>0.2</mu1>
    <mu2>0.2</mu2>
    <selfCollide>true</selfCollide>
  </gazebo>
  <gazebo reference="Encoder_1">
    <material>Gazebo/Silver</material>
    <mu1>0.2</mu1>
    <mu2>0.2</mu2>
    <selfCollide>true</selfCollide>
  </gazebo>
  <link name="base_link">
    <inertial>
      <origin rpy="0 0 0" xyz="3.592221998570457e-17 0.0 0.15501107810631898"/>
      <mass value="11.924986949735343"/>
      <inertia ixx="0.100382" ixy="0.0" ixz="-0.0" iyy="0.100382" iyz="0.0" izz="0.009738"/>
    </inertial>
    <visual>
      <origin rpy="0 0 0" xyz="0 0 0"/>
      <geometry>
        <mesh filename="../meshes/base_link.stl" scale="0.001 0.001 0.001"/>
      </geometry>
      <material name="silver"/>
    </visual>
    <collision>
      <origin rpy="0 0 0" xyz="0 0 0"/>
      <geometry>
        <mesh filename="../meshes/base_link.stl" scale="0.001 0.001 0.001"/>
      </geometry>
    </collision>
  </link>
  <link name="Pendel_1">
    <inertial>
      <origin rpy="0 0 0" xyz="7.53053905616492e-07 -0.057182054209378205 -0.12050399497646608"/>
      <mass value="0.01740539597679812"/>
      <inertia ixx="0.000136" ixy="0.0" ixz="0.0" iyy="0.000131" iyz="-1.6e-05" izz="6e-06"/>
    </inertial>
    <visual>
      <origin rpy="0 0 0" xyz="-0.0 0.0295 -0.335002"/>
      <geometry>
        <mesh filename="../meshes/Pendel_1.stl" scale="0.001 0.001 0.001"/>
      </geometry>
      <material name="silver"/>
    </visual>
    <collision>
      <origin rpy="0 0 0" xyz="-0.0 0.0295 -0.335002"/>
      <geometry>
        <mesh filename="../meshes/Pendel_1.stl" scale="0.001 0.001 0.001"/>
      </geometry>
    </collision>
  </link>
  <link name="Encoder_1">
    <inertial>
      <origin rpy="0 0 0" xyz="4.2822283207196315e-08 -0.00013534763535349713 0.01901143495877572"/>
      <mass value="0.1023589961334875"/>
      <inertia ixx="1.8e-05" ixy="-0.0" ixz="0.0" iyy="2e-05" iyz="-0.0" izz="1.8e-05"/>
    </inertial>
    <visual>
      <origin rpy="0 0 0" xyz="-0.0 -0.0 -0.316"/>
      <geometry>
        <mesh filename="../meshes/Encoder_1.stl" scale="0.001 0.001 0.001"/>
      </geometry>
      <material name="silver"/>
    </visual>
    <collision>
      <origin rpy="0 0 0" xyz="-0.0 -0.0 -0.316"/>
      <geometry>
        <mesh filename="../meshes/Encoder_1.stl" scale="0.001 0.001 0.001"/>
      </geometry>
    </collision>
  </link>
  <joint name="pendelGelenk" type="continuous">
    <origin rpy="0 0 0" xyz="0.0 -0.0295 0.019002"/>
    <parent link="Encoder_1"/>
    <child link="Pendel_1"/>
    <axis xyz="0.0 -1.0 0.0"/>
  </joint>
  <joint name="rotaryGelenk" type="revolute">
    <origin rpy="0 0 0" xyz="0.0 0.0 0.316"/>
    <parent link="base_link"/>
    <child link="Encoder_1"/>
    <axis xyz="0.0 0.0 1.0"/>
    <limit effort="100" lower="-6.283185" upper="0.0" velocity="100"/>
  </joint>
</robot>
